<?xml version='1.0' encoding='utf-8'?>
<robot name="franka_panda">
	<material name="white">
		<color rgba="1 1 1 1" />
	</material>
	<material name="gray">
		<color rgba="0.2 0.2 0.2 1" />
	</material>

	<link name="link0">
		<inertial>
			<origin xyz="0 0 0.05" rpy="0 0 0" />
			<mass value="4" />
			<inertia ixx="0.4" iyy="0.4" izz="0.4" ixy="0" ixz="0" iyz="0" />
		</inertial>
		<visual>
			<geometry>
				<mesh filename="visual/link0.dae" />
			</geometry>
			<material name="white" />
		</visual>
		<collision>
			<geometry>
				<mesh filename="collision/link0.stl" />
			</geometry>
		</collision>
	</link>
	<link name="link1">
		<inertial>
			<origin xyz="0 0 -0.07" rpy="0 0 0" />
			<mass value="3" />
			<inertia ixx="0.3" iyy="0.3" izz="0.3" ixy="0" ixz="0" iyz="0" />
		</inertial>
		<visual>
			<geometry>
				<mesh filename="visual/link1.dae" />
			</geometry>
			<material name="white" />
		</visual>
		<collision>
			<geometry>
				<mesh filename="collision/link1.stl" />
			</geometry>
		</collision>
	</link>
	<link name="link2">
		<inertial>
			<origin xyz="0 -0.1 0" rpy="0 0 0" />
			<mass value="3" />
			<inertia ixx="0.3" iyy="0.3" izz="0.3" ixy="0" ixz="0" iyz="0" />
		</inertial>
		<visual>
			<geometry>
				<mesh filename="visual/link2.dae" />
			</geometry>
			<material name="white" />
		</visual>
		<collision>
			<geometry>
				<mesh filename="collision/link2.stl" />
			</geometry>
		</collision>
	</link>
	<link name="link3">
		<inertial>
			<origin xyz="0.04 0 -0.05" rpy="0 0 0" />
			<mass value="2" />
			<inertia ixx="0.2" iyy="0.2" izz="0.2" ixy="0" ixz="0" iyz="0" />
		</inertial>
		<visual>
			<geometry>
				<mesh filename="visual/link3.dae" />
			</geometry>
			<material name="white" />
		</visual>
		<collision>
			<geometry>
				<mesh filename="collision/link3.stl" />
			</geometry>
		</collision>
	</link>
	<link name="link4">
		<inertial>
			<origin xyz="-0.04 0.05 0" rpy="0 0 0" />
			<mass value="2" />
			<inertia ixx="0.2" iyy="0.2" izz="0.2" ixy="0" ixz="0" iyz="0" />
		</inertial>
		<visual>
			<geometry>
				<mesh filename="visual/link4.dae" />
			</geometry>
			<material name="white" />
		</visual>
		<collision>
			<geometry>
				<mesh filename="collision/link4.stl" />
			</geometry>
		</collision>
	</link>
	<link name="link5">
		<inertial>
			<origin xyz="0 0 -0.15" rpy="0 0 0" />
			<mass value="2" />
			<inertia ixx="0.2" iyy="0.2" izz="0.2" ixy="0" ixz="0" iyz="0" />
		</inertial>
		<visual>
			<geometry>
				<mesh filename="visual/link5.dae" />
			</geometry>
			<material name="white" />
		</visual>
		<collision>
			<geometry>
				<mesh filename="collision/link5.stl" />
			</geometry>
		</collision>
	</link>
	<link name="link6">
		<inertial>
			<origin xyz="0.06 0 0" rpy="0 0 0" />
			<mass value="1.5" />
			<inertia ixx="0.1" iyy="0.1" izz="0.1" ixy="0" ixz="0" iyz="0" />
		</inertial>
		<visual>
			<geometry>
				<mesh filename="visual/link6.dae" />
			</geometry>
			<material name="white" />
		</visual>
		<collision>
			<geometry>
				<mesh filename="collision/link6.stl" />
			</geometry>
		</collision>
	</link>
	<link name="link7">
		<inertial>
			<origin xyz="0 0 0.08" rpy="0 0 0" />
			<mass value="0.5" />
			<inertia ixx="0.05" iyy="0.05" izz="0.05" ixy="0" ixz="0" iyz="0" />
		</inertial>
		<visual>
			<origin xyz="0 0 0" rpy="0 0 0" />
			<geometry>
				<mesh filename="visual/link7.dae" />
			</geometry>
			<material name="gray" />
		</visual>
		<!-- <visual> -->
		<!-- 	<origin xyz="0 0 0.107" rpy="0 0 -0.78539816339" /> -->
		<!-- 	<geometry> -->
		<!-- 		<mesh filename="visual/hand.dae" /> -->
		<!-- 	</geometry> -->
		<!-- 	<material name="white" /> -->
		<!-- </visual> -->
		<!-- <visual> -->
		<!-- 	<origin xyz="0 0 0.1654" rpy="0 0 2.35619449019" /> -->
		<!-- 	<geometry> -->
		<!-- 		<mesh filename="visual/finger.dae" /> -->
		<!-- 	</geometry> -->
		<!-- 	<material name="gray" /> -->
		<!-- </visual> -->
		<!-- <visual> -->
		<!-- 	<origin xyz="0 0 0.1654" rpy="0 0 -0.78539816339" /> -->
		<!-- 	<geometry> -->
		<!-- 		<mesh filename="visual/finger.dae" /> -->
		<!-- 	</geometry> -->
		<!-- 	<material name="gray" /> -->
		<!-- </visual> -->
		<collision>
			<geometry>
				<mesh filename="collision/link7.stl" />
			</geometry>
		</collision>
		<!-- <collision> -->
		<!-- 	<origin xyz="0 0 0.107" rpy="0 0 -0.78539816339" /> -->
		<!-- 	<geometry> -->
		<!-- 		<mesh filename="collision/hand.stl" /> -->
		<!-- 	</geometry> -->
		<!-- </collision> -->
		<!-- <collision> -->
		<!-- 	<origin xyz="0 0 0.1654" rpy="0 0 2.35619449019" /> -->
		<!-- 	<geometry> -->
		<!-- 		<mesh filename="collision/finger.stl" /> -->
		<!-- 	</geometry> -->
		<!-- </collision> -->
		<!-- <collision> -->
		<!-- 	<origin xyz="0 0 0.1654" rpy="0 0 -0.78539816339" /> -->
		<!-- 	<geometry> -->
		<!-- 		<mesh filename="collision/finger.stl" /> -->
		<!-- 	</geometry> -->
		<!-- </collision> -->
	</link>

	<joint name="joint1" type="revolute">
		<safety_controller k_position="100.0" k_velocity="40.0" soft_lower_limit="-2.8973" soft_upper_limit="2.8973" />
		<origin rpy="0 0 0" xyz="0 0 0.333" />
		<parent link="link0" />
		<child link="link1" />
		<axis xyz="0 0 1" />
		<!-- <dynamics damping="1" friction="0" coulomb="0.5" /> -->
		<limit effort="87" lower="-2.8973" upper="2.8973" velocity="2.1750" />
	</joint>
	<joint name="joint2" type="revolute">
		<safety_controller k_position="100.0" k_velocity="40.0" soft_lower_limit="-1.7628" soft_upper_limit="1.7628" />
		<origin rpy="-1.57079632679 0 0" xyz="0 0 0" />
		<parent link="link1" />
		<child link="link2" />
		<axis xyz="0 0 1" />
		<!-- <dynamics damping="1" friction="0" coulomb="0.5" /> -->
		<calibration falling="-45.0" />
		<limit effort="87" lower="-1.7628" upper="1.7628" velocity="2.1750" />
	</joint>
	<joint name="joint3" type="revolute">
		<safety_controller k_position="100.0" k_velocity="40.0" soft_lower_limit="-2.8973" soft_upper_limit="2.8973" />
		<origin rpy="1.57079632679 0 0" xyz="0 -0.316 0" />
		<parent link="link2" />
		<child link="link3" />
		<axis xyz="0 0 1" />
		<!-- <dynamics damping="1" friction="0" coulomb="0.5" /> -->
		<limit effort="87" lower="-2.8973" upper="2.8973" velocity="2.1750" />
	</joint>
	<joint name="joint4" type="revolute">
		<safety_controller k_position="100.0" k_velocity="40.0" soft_lower_limit="-3.0718" soft_upper_limit="-0.0698" />
		<origin rpy="1.57079632679 0 0" xyz="0.0825 0 0" />
		<parent link="link3" />
		<child link="link4" />
		<axis xyz="0 0 1" />
		<!-- <dynamics damping="1" friction="0" coulomb="0.5" /> -->
		<calibration falling="-125.0" />
		<limit effort="87" lower="-3.0718" upper="-0.0698" velocity="2.1750" />
	</joint>
	<joint name="joint5" type="revolute">
		<safety_controller k_position="100.0" k_velocity="40.0" soft_lower_limit="-2.8973" soft_upper_limit="2.8973" />
		<origin rpy="-1.57079632679 0 0" xyz="-0.0825 0.384 0" />
		<parent link="link4" />
		<child link="link5" />
		<axis xyz="0 0 1" />
		<!-- <dynamics damping="1" friction="0" coulomb="0.5" /> -->
		<limit effort="12" lower="-2.8973" upper="2.8973" velocity="2.6100" />
	</joint>
	<joint name="joint6" type="revolute">
		<safety_controller k_position="100.0" k_velocity="40.0" soft_lower_limit="-0.0175" soft_upper_limit="3.7525" />
		<origin rpy="1.57079632679 0 0" xyz="0 0 0" />
		<parent link="link5" />
		<child link="link6" />
		<axis xyz="0 0 1" />
		<!-- <dynamics damping="1" friction="0" coulomb="0.5" /> -->
		<calibration falling="80.0" />
		<limit effort="12" lower="-0.0175" upper="3.7525" velocity="2.6100" />
	</joint>
	<joint name="joint7" type="revolute">
		<safety_controller k_position="100.0" k_velocity="40.0" soft_lower_limit="-2.8973" soft_upper_limit="2.8973" />
		<origin rpy="1.57079632679 0 0" xyz="0.088 0 0" />
		<parent link="link6" />
		<child link="link7" />
		<axis xyz="0 0 1" />
		<!-- <dynamics damping="1" friction="0" coulomb="0.5" /> -->
		<limit effort="12" lower="-2.8973" upper="2.8973" velocity="2.6100" />
	</joint>

</robot>
