<?xml version='1.0' encoding='utf-8' ?>
<robot name="franka_panda">
	<material name="white">
		<color rgba="1 1 1 1" />
	</material>
	<material name="gray">
		<color rgba="0.2 0.2 0.2 1" />
	</material>
	<material name="metal">
		<color rgba="0.792156862745098 0.819607843137255 0.933333333333333 1" />
	</material>
	<material name="black">
		<color rgba="0.1 0.1 0.1 1" />
	</material>
	<material name="collision">
		<color rgba="1 0 0 1" />
	</material>

	<link name="link0">
		<inertial>
			<origin xyz="0 0 0.05" rpy="0 0 0" />
			<mass value="4" />
			<inertia ixx="0.4" iyy="0.4" izz="0.4" ixy="0" ixz="0" iyz="0" />
		</inertial>
		<visual>
			<geometry>
				<mesh filename="visual/link0.dae" />
			</geometry>
			<material name="white" />
		</visual>
		<collision>
			<geometry>
				<mesh filename="collision/link0.stl" />
			</geometry>
		</collision>
	</link>
	<link name="link1">
		<inertial>
			<origin xyz="0 0 -0.07" rpy="0 0 0" />
			<mass value="3" />
			<inertia ixx="0.3" iyy="0.3" izz="0.3" ixy="0" ixz="0" iyz="0" />
		</inertial>
		<visual>
			<geometry>
				<mesh filename="visual/link1.dae" />
			</geometry>
			<material name="white" />
		</visual>
		<collision>
			<geometry>
				<mesh filename="collision/link1.stl" />
			</geometry>
		</collision>
	</link>
	<link name="link2">
		<inertial>
			<origin xyz="0 -0.1 0" rpy="0 0 0" />
			<mass value="3" />
			<inertia ixx="0.3" iyy="0.3" izz="0.3" ixy="0" ixz="0" iyz="0" />
		</inertial>
		<visual>
			<geometry>
				<mesh filename="visual/link2.dae" />
			</geometry>
			<material name="white" />
		</visual>
		<collision>
			<geometry>
				<mesh filename="collision/link2.stl" />
			</geometry>
		</collision>
	</link>
	<link name="link3">
		<inertial>
			<origin xyz="0.04 0 -0.05" rpy="0 0 0" />
			<mass value="2" />
			<inertia ixx="0.2" iyy="0.2" izz="0.2" ixy="0" ixz="0" iyz="0" />
		</inertial>
		<visual>
			<geometry>
				<mesh filename="visual/link3.dae" />
			</geometry>
			<material name="white" />
		</visual>
		<collision>
			<geometry>
				<mesh filename="collision/link3.stl" />
			</geometry>
		</collision>
	</link>
	<link name="link4">
		<inertial>
			<origin xyz="-0.04 0.05 0" rpy="0 0 0" />
			<mass value="2" />
			<inertia ixx="0.2" iyy="0.2" izz="0.2" ixy="0" ixz="0" iyz="0" />
		</inertial>
		<visual>
			<geometry>
				<mesh filename="visual/link4.dae" />
			</geometry>
			<material name="white" />
		</visual>
		<collision>
			<geometry>
				<mesh filename="collision/link4.stl" />
			</geometry>
		</collision>
	</link>
	<link name="link5">
		<inertial>
			<origin xyz="0 0 -0.15" rpy="0 0 0" />
			<mass value="2" />
			<inertia ixx="0.2" iyy="0.2" izz="0.2" ixy="0" ixz="0" iyz="0" />
		</inertial>
		<visual>
			<geometry>
				<mesh filename="visual/link5.dae" />
			</geometry>
			<material name="white" />
		</visual>
		<collision>
			<geometry>
				<mesh filename="collision/link5.stl" />
			</geometry>
		</collision>
	</link>
	<link name="link6">
		<inertial>
			<origin xyz="0.06 0 0" rpy="0 0 0" />
			<mass value="1.5" />
			<inertia ixx="0.1" iyy="0.1" izz="0.1" ixy="0" ixz="0" iyz="0" />
		</inertial>
		<visual>
			<geometry>
				<mesh filename="visual/link6.dae" />
			</geometry>
			<material name="white" />
		</visual>
		<collision>
			<geometry>
				<mesh filename="collision/link6.stl" />
			</geometry>
		</collision>
	</link>
	<link name="link7">
		<inertial>
			<origin xyz="0 0 0.08" rpy="0 0 0" />
			<mass value="0.5" />
			<inertia ixx="0.05" iyy="0.05" izz="0.05" ixy="0" ixz="0" iyz="0" />
		</inertial>
		<visual>
			<origin xyz="0 0 0" rpy="0 0 0" />
			<geometry>
				<mesh filename="visual/link7.dae" />
			</geometry>
			<material name="gray" />
		</visual>
		<!--<visual>-->
		<!--    <origin xyz="0 0 0.107" rpy="0 0 -0.78539816339" />-->
		<!--    <geometry>-->
		<!--        <mesh filename="visual/hand.dae" />-->
		<!--    </geometry>-->
		<!--    <material name="white" />-->
		<!--</visual>-->
		<!--<visual>-->
		<!--    <origin xyz="0 0 0.1654" rpy="0 0 2.35619449019" />-->
		<!--    <geometry>-->
		<!--        <mesh filename="visual/finger.dae" />-->
		<!--    </geometry>-->
		<!--    <material name="gray" />-->
		<!--</visual>-->
		<!--<visual>-->
		<!--    <origin xyz="0 0 0.1654" rpy="0 0 -0.78539816339" />-->
		<!--    <geometry>-->
		<!--        <mesh filename="visual/finger.dae" />-->
		<!--    </geometry>-->
		<!--    <material name="gray" />-->
		<!--</visual>-->
		<collision>
			<geometry>
				<mesh filename="collision/link7.stl" />
			</geometry>
		</collision>
		<!--<collision>-->
		<!--    <origin xyz="0 0 0.107" rpy="0 0 -0.78539816339" />-->
		<!--    <geometry>-->
		<!--        <mesh filename="collision/hand.stl" />-->
		<!--    </geometry>-->
		<!--</collision>-->
		<!--<collision>-->
		<!--    <origin xyz="0 0 0.1654" rpy="0 0 2.35619449019" />-->
		<!--    <geometry>-->
		<!--        <mesh filename="collision/finger.stl" />-->
		<!--    </geometry>-->
		<!--</collision>-->
		<!--<collision>-->
		<!--    <origin xyz="0 0 0.1654" rpy="0 0 -0.78539816339" />-->
		<!--    <geometry>-->
		<!--        <mesh filename="collision/finger.stl" />-->
		<!--    </geometry>-->
		<!--</collision>-->
	</link>

	<joint name="joint1" type="revolute">
		<safety_controller k_position="100.0" k_velocity="40.0" soft_lower_limit="-2.8973" soft_upper_limit="2.8973" />
		<origin rpy="0 0 0" xyz="0 0 0.333" />
		<parent link="link0" />
		<child link="link1" />
		<axis xyz="0 0 1" />
		<!-- <dynamics damping="1" friction="0" coulomb="0.5" /> -->
		<limit effort="87" lower="-2.8973" upper="2.8973" velocity="2.1750" />
	</joint>
	<joint name="joint2" type="revolute">
		<safety_controller k_position="100.0" k_velocity="40.0" soft_lower_limit="-1.7628" soft_upper_limit="1.7628" />
		<origin rpy="-1.57079632679 0 0" xyz="0 0 0" />
		<parent link="link1" />
		<child link="link2" />
		<axis xyz="0 0 1" />
		<!-- <dynamics damping="1" friction="0" coulomb="0.5" /> -->
		<calibration falling="-45.0" />
		<limit effort="87" lower="-1.7628" upper="1.7628" velocity="2.1750" />
	</joint>
	<joint name="joint3" type="revolute">
		<safety_controller k_position="100.0" k_velocity="40.0" soft_lower_limit="-2.8973" soft_upper_limit="2.8973" />
		<origin rpy="1.57079632679 0 0" xyz="0 -0.316 0" />
		<parent link="link2" />
		<child link="link3" />
		<axis xyz="0 0 1" />
		<!-- <dynamics damping="1" friction="0" coulomb="0.5" /> -->
		<limit effort="87" lower="-2.8973" upper="2.8973" velocity="2.1750" />
	</joint>
	<joint name="joint4" type="revolute">
		<safety_controller k_position="100.0" k_velocity="40.0" soft_lower_limit="-3.0718" soft_upper_limit="-0.0698" />
		<origin rpy="1.57079632679 0 0" xyz="0.0825 0 0" />
		<parent link="link3" />
		<child link="link4" />
		<axis xyz="0 0 1" />
		<!-- <dynamics damping="1" friction="0" coulomb="0.5" /> -->
		<calibration falling="-125.0" />
		<limit effort="87" lower="-3.0718" upper="-0.0698" velocity="2.1750" />
	</joint>
	<joint name="joint5" type="revolute">
		<safety_controller k_position="100.0" k_velocity="40.0" soft_lower_limit="-2.8973" soft_upper_limit="2.8973" />
		<origin rpy="-1.57079632679 0 0" xyz="-0.0825 0.384 0" />
		<parent link="link4" />
		<child link="link5" />
		<axis xyz="0 0 1" />
		<!-- <dynamics damping="1" friction="0" coulomb="0.5" /> -->
		<limit effort="12" lower="-2.8973" upper="2.8973" velocity="2.6100" />
	</joint>
	<joint name="joint6" type="revolute">
		<safety_controller k_position="100.0" k_velocity="40.0" soft_lower_limit="-0.0175" soft_upper_limit="3.7525" />
		<origin rpy="1.57079632679 0 0" xyz="0 0 0" />
		<parent link="link5" />
		<child link="link6" />
		<axis xyz="0 0 1" />
		<!-- <dynamics damping="1" friction="0" coulomb="0.5" /> -->
		<calibration falling="80.0" />
		<limit effort="12" lower="-0.0175" upper="3.7525" velocity="2.6100" />
	</joint>
	<joint name="joint7" type="revolute">
		<safety_controller k_position="100.0" k_velocity="40.0" soft_lower_limit="-2.8973" soft_upper_limit="2.8973" />
		<origin rpy="1.57079632679 0 0" xyz="0.088 0 0" />
		<parent link="link6" />
		<child link="link7" />
		<axis xyz="0 0 1" />
		<!-- <dynamics damping="1" friction="0" coulomb="0.5" /> -->
		<!--<dynamics damping="0.8" friction="0.8" coulomb="0.5" />-->
		<limit effort="12" lower="-20.8973" upper="20.8973" velocity="2.6100" />
	</joint>

	<link name="robotiq_arg2f_base_link">
		<inertial>
			<origin rpy="0 0 0" xyz="0 0 0.03145" />
			<mass value="0.5" />
			<inertia ixx="0.05" ixy="0" ixz="0" iyy="0.05" iyz="0" izz="0.05" />
		</inertial>
		<visual>
			<origin rpy="0 0 0" xyz="0 0 0" />
			<geometry>
				<mesh filename="visual/robotiq_arg2f_85_base_link.dae" scale="0.001 0.001 0.001" />
			</geometry>
			<material name="black" />
		</visual>
		<collision>
			<origin rpy="0 0 0" xyz="0 0 0" />
			<geometry>
				<mesh filename="collision/robotiq_arg2f_base_link.stl" />
			</geometry>
		</collision>
	</link>
	<link name="left_outer_knuckle">
		<inertial>
			<origin xyz="-0.000200000000003065 0.0199435877845359 0.0292245259211331" rpy="0 0 0" />
			<mass value="0.00853198276973456" />
			<inertia ixx="2.89328108496468E-06" ixy="-1.57935047237397E-19" ixz="-1.93980378593255E-19" iyy="1.86719750325683E-06" iyz="-1.21858577871576E-06" izz="1.21905238907251E-06" />
		</inertial>
		<visual>
			<origin rpy="0 0 0" xyz="0 0 0" />
			<geometry>
				<mesh filename="visual/robotiq_arg2f_85_outer_knuckle.dae" scale="0.001 0.001 0.001" />
			</geometry>
			<material name="metal" />
		</visual>
		<collision>
			<origin rpy="0 0 0" xyz="0 0 -1" />
			<geometry>
				<box size="0 0 0" />
			</geometry>
		</collision>
	</link>
	<link name="left_outer_finger">
		<inertial>
			<origin xyz="0.00030115855001899 0.0373907951953854 -0.0208027427000385" rpy="0 0 0" />
			<mass value="0.022614240507152" />
			<inertia ixx="1.52518312458174E-05" ixy="9.76583423954399E-10" ixz="-5.43838577022588E-10" iyy="6.17694243867776E-06" iyz="6.78636130740228E-06" izz="1.16494917907219E-05" />
		</inertial>
		<visual>
			<origin rpy="0 0 0" xyz="0 0 0" />
			<geometry>
				<mesh filename="visual/robotiq_arg2f_85_outer_finger.dae" scale="0.001 0.001 0.001" />
			</geometry>
			<material name="black" />
		</visual>
	</link>
	<link name="left_inner_finger">
		<inertial>
			<origin xyz="0.000299999999999317 0.0160078233491243 -0.0136945669206257" rpy="0 0 0" />
			<mass value="0.0104003125914103" />
			<inertia ixx="2.71909453810972E-06" ixy="1.35402465472579E-21" ixz="-7.1817349065269E-22" iyy="7.69100314106116E-07" iyz="6.74715432769696E-07" izz="2.30315190420171E-06" />
		</inertial>
		<visual>
			<origin rpy="0 0 0" xyz="0 0 0" />
			<geometry>
				<mesh filename="visual/robotiq_arg2f_85_inner_finger.dae" scale="0.001 0.001 0.001" />
			</geometry>
			<material name="black" />
		</visual>
		<collision>
			<origin rpy="0 0 0" xyz="0 0 -1" />
			<geometry>
				<box size="0 0 0" />
			</geometry>
		</collision>
	</link>
	<link name="left_inner_finger_pad">
		<inertial>
			<origin xyz="0 0 0" rpy="0 0 0" />
			<mass value="0" />
			<inertia ixx="0" ixy="0" ixz="0" iyy="0" iyz="0" izz="0" />
		</inertial>
		<visual>
			<origin rpy="0 0 0" xyz="0 0 0" />
			<geometry>
				<box size="0.022 0.00635 0.0375" />
			</geometry>
			<material name="white" />
		</visual>
		<collision>
			<origin rpy="0 0 0" xyz="0 0 -1" />
			<geometry>
				<box size="0 0 0" />
			</geometry>
		</collision>
	</link>
	<link name="left_inner_knuckle">
		<inertial>
			<origin xyz="0.000123011831763771 0.0507850843201817 0.00103968640075166" rpy="0 0 0" />
			<mass value="0.0271177346495152" />
			<inertia ixx="2.61910379223783E-05" ixy="-2.43616858946494E-07" ixz="-6.37789906117123E-09" iyy="2.8270243746167E-06" iyz="-5.37200748039765E-07" izz="2.83695868220296E-05" />
		</inertial>
		<visual>
			<origin rpy="0 0 0" xyz="0 0 0" />
			<geometry>
				<mesh filename="visual/robotiq_arg2f_85_inner_knuckle.dae" scale="0.001 0.001 0.001" />
			</geometry>
			<material name="black" />
		</visual>
		<collision>
			<origin rpy="0 0 0" xyz="0 0 -1" />
			<geometry>
				<box size="0 0 0" />
			</geometry>
		</collision>
	</link>
	<link name="right_outer_knuckle">
		<inertial>
			<origin xyz="-0.000200000000003065 0.0199435877845359 0.0292245259211331" rpy="0 0 0" />
			<mass value="0.00853198276973456" />
			<inertia ixx="2.89328108496468E-06" ixy="-1.57935047237397E-19" ixz="-1.93980378593255E-19" iyy="1.86719750325683E-06" iyz="-1.21858577871576E-06" izz="1.21905238907251E-06" />
		</inertial>
		<visual>
			<origin rpy="0 0 0" xyz="0 0 0" />
			<geometry>
				<mesh filename="visual/robotiq_arg2f_85_outer_knuckle.dae" scale="0.001 0.001 0.001" />
			</geometry>
			<material name="metal" />
		</visual>
		<collision>
			<origin rpy="0 0 0" xyz="0 0 -1" />
			<geometry>
				<box size="0 0 0" />
			</geometry>
		</collision>
	</link>
	<link name="right_outer_finger">
		<inertial>
			<origin xyz="0.00030115855001899 0.0373907951953854 -0.0208027427000385" rpy="0 0 0" />
			<mass value="0.022614240507152" />
			<inertia ixx="1.52518312458174E-05" ixy="9.76583423954399E-10" ixz="-5.43838577022588E-10" iyy="6.17694243867776E-06" iyz="6.78636130740228E-06" izz="1.16494917907219E-05" />
		</inertial>
		<visual>
			<origin rpy="0 0 0" xyz="0 0 0" />
			<geometry>
				<mesh filename="visual/robotiq_arg2f_85_outer_finger.dae" scale="0.001 0.001 0.001" />
			</geometry>
			<material name="black" />
		</visual>
		<collision>
			<origin rpy="0 0 0" xyz="0 0 -1" />
			<geometry>
				<box size="0 0 0" />
			</geometry>
		</collision>
	</link>
	<link name="right_inner_finger">
		<inertial>
			<origin xyz="0.000299999999999317 0.0160078233491243 -0.0136945669206257" rpy="0 0 0" />
			<mass value="0.0104003125914103" />
			<inertia ixx="2.71909453810972E-06" ixy="1.35402465472579E-21" ixz="-7.1817349065269E-22" iyy="7.69100314106116E-07" iyz="6.74715432769696E-07" izz="2.30315190420171E-06" />
		</inertial>
		<visual>
			<origin rpy="0 0 0" xyz="0 0 0" />
			<geometry>
				<mesh filename="visual/robotiq_arg2f_85_inner_finger.dae" scale="0.001 0.001 0.001" />
			</geometry>
			<material name="black" />
		</visual>
		<collision>
			<origin rpy="0 0 0" xyz="0 0 -1" />
			<geometry>
				<box size="0 0 0" />
			</geometry>
		</collision>
	</link>
	<link name="right_inner_finger_pad">
		<inertial>
			<origin xyz="0 0 0" rpy="0 0 0" />
			<mass value="0.01" />
			<inertia ixx="0" ixy="0" ixz="0" iyy="0" iyz="0" izz="0" />
		</inertial>
		<visual>
			<origin rpy="0 0 0" xyz="0 0 0" />
			<geometry>
				<box size="0.022 0.00635 0.0375" />
			</geometry>
			<material name="white" />
		</visual>
		<collision>
			<origin rpy="0 0 0" xyz="0 0 -1" />
			<geometry>
				<box size="0 0 0" />
			</geometry>
		</collision>
	</link>
	<link name="right_inner_knuckle">
		<inertial>
			<origin xyz="0.000123011831763771 0.0507850843201817 0.00103968640075166" rpy="0 0 0" />
			<mass value="0.0271177346495152" />
			<inertia ixx="2.61910379223783E-05" ixy="-2.43616858946494E-07" ixz="-6.37789906117123E-09" iyy="2.8270243746167E-06" iyz="-5.37200748039765E-07" izz="2.83695868220296E-05" />
		</inertial>
		<visual>
			<origin rpy="0 0 0" xyz="0 0 0" />
			<geometry>
				<mesh filename="visual/robotiq_arg2f_85_inner_knuckle.dae" scale="0.001 0.001 0.001" />
			</geometry>
			<material name="black" />
		</visual>
		<collision>
			<origin rpy="0 0 0" xyz="0 0 -1" />
			<geometry>
				<box size="0 0 0" />
			</geometry>
		</collision>
	</link>
	<link name="left_inner_finger_pad_collision">
		<inertial>
			<origin xyz="0 0 0" rpy="0 0 0" />
			<mass value="0.1" />
			<inertia ixx="0.05" ixy="0" ixz="0" iyy="0.05" iyz="0" izz="0.05" />
		</inertial>
		<visual>
			<origin rpy="0 0 0" xyz="0 0 -0.01" />
			<geometry>
				<!-- <box size="0.022 0.00635 0.0575" /> -->
				<box size="0.002 0.00035 0.0075" />
			</geometry>
			<material name="collision" />
		</visual>
		<collision>
			<origin rpy="0 0 0" xyz="0 0 -0.01" />
			<geometry>
				<box size="0.022 0.00635 0.0575" />
			</geometry>
		</collision>
	</link>
	<link name="right_inner_finger_pad_collision">
		<inertial>
			<origin xyz="0 0 0" rpy="0 0 0" />
			<mass value="0.1" />
			<inertia ixx="0.05" ixy="0" ixz="0" iyy="0.05" iyz="0" izz="0.05" />
		</inertial>
		<visual>
			<origin rpy="0 0 0" xyz="0 0 -0.01" />
			<geometry>
				<!-- <box size="0.022 0.00635 0.0575" /> -->
				<box size="0.002 0.00035 0.0075" />
			</geometry>
			<material name="collision" />
		</visual>
		<collision>
			<origin rpy="0 0 0" xyz="0 0 -0.01" />
			<geometry>
				<box size="0.022 0.00635 0.0575" />
			</geometry>
		</collision>
	</link>

	<joint name="left_inner_finger_pad_prismatic" type="prismatic">
		<origin rpy="0 0 0" xyz="0 -0.046 0.144" />
		<parent link="robotiq_arg2f_base_link" />
		<child link="left_inner_finger_pad_collision" />
		<axis xyz="0 1 0" />
		<limit effort="10" lower="-0.002" upper="0.042" velocity="2.1" />
	</joint>
	<joint name="right_inner_finger_pad_prismatic" type="prismatic">
		<origin rpy="0 0 0" xyz="0 0.046 0.144" />
		<parent link="robotiq_arg2f_base_link" />
		<child link="right_inner_finger_pad_collision" />
		<axis xyz="0 1 0" />
		<limit effort="1000" lower="-0.042" upper="0.002" velocity="2.1" />
	</joint>

	<joint name="gripper_mount" type="fixed">
		<origin rpy="0 0 0" xyz="0 0 0.107" />
		<parent link="link7" />
		<child link="robotiq_arg2f_base_link" />
	</joint>
	<joint name="finger_joint" type="revolute">
		<origin rpy="0 0 3.14159265359" xyz="0 -0.0306011 0.054904" />
		<parent link="robotiq_arg2f_base_link" />
		<child link="left_outer_knuckle" />
		<axis xyz="1 0 0" />
		<limit effort="10" lower="0" upper="0.8" velocity="2.0" />
	</joint>
	<joint name="left_outer_finger_joint" type="fixed">
		<origin rpy="0 0 0" xyz="0 0.0315 -0.0041" />
		<parent link="left_outer_knuckle" />
		<child link="left_outer_finger" />
		<axis xyz="1 0 0" />
	</joint>
	<joint name="left_inner_knuckle_joint" type="revolute">
		<origin rpy="0 0 3.14159265359" xyz="0 -0.0127 0.06142" />
		<parent link="robotiq_arg2f_base_link" />
		<child link="left_inner_knuckle" />
		<axis xyz="1 0 0" />
		<limit effort="10" lower="0" upper="0.8757" velocity="2.0" />
		<mimic joint="finger_joint" multiplier="1" offset="0" />
	</joint>
	<joint name="left_inner_finger_joint" type="revolute">
		<origin rpy="0 0 0" xyz="0 0.0061 0.0471" />
		<parent link="left_outer_finger" />
		<child link="left_inner_finger" />
		<axis xyz="1 0 0" />
		<limit effort="10" lower="-0.8757" upper="0" velocity="2.0" />
		<mimic joint="finger_joint" multiplier="-1" offset="0" />
	</joint>
	<joint name="right_outer_knuckle_joint" type="revolute">
		<origin rpy="0 0 0" xyz="0 0.0306011 0.054904" />
		<parent link="robotiq_arg2f_base_link" />
		<child link="right_outer_knuckle" />
		<axis xyz="1 0 0" />
		<limit effort="10" lower="0" upper="0.81" velocity="2.0" />
		<mimic joint="finger_joint" multiplier="1" offset="0" />
	</joint>
	<joint name="right_outer_finger_joint" type="fixed">
		<origin rpy="0 0 0" xyz="0 0.0315 -0.0041" />
		<parent link="right_outer_knuckle" />
		<child link="right_outer_finger" />
		<axis xyz="1 0 0" />
	</joint>
	<joint name="right_inner_knuckle_joint" type="revolute">
		<origin rpy="0 0 0.0" xyz="0 0.0127 0.06142" />
		<parent link="robotiq_arg2f_base_link" />
		<child link="right_inner_knuckle" />
		<axis xyz="1 0 0" />
		<limit effort="10" lower="0" upper="0.8757" velocity="2.0" />
		<mimic joint="finger_joint" multiplier="1" offset="0" />
	</joint>
	<joint name="right_inner_finger_joint" type="revolute">
		<origin rpy="0 0 0" xyz="0 0.0061 0.0471" />
		<parent link="right_outer_finger" />
		<child link="right_inner_finger" />
		<axis xyz="1 0 0" />
		<limit effort="10" lower="-0.8757" upper="0" velocity="2.0" />
		<mimic joint="finger_joint" multiplier="-1" offset="0" />
	</joint>
	<joint name="left_inner_finger_pad_joint" type="fixed">
		<origin rpy="0 0 0" xyz="0 -0.0220203446692936 0.03242" />
		<parent link="left_inner_finger" />
		<child link="left_inner_finger_pad" />
		<axis xyz="0 0 1" />
	</joint>
	<joint name="right_inner_finger_pad_joint" type="fixed">
		<origin rpy="0 0 0" xyz="0 -0.0220203446692936 0.03242" />
		<parent link="right_inner_finger" />
		<child link="right_inner_finger_pad" />
		<axis xyz="0 0 1" />
	</joint>
</robot>
